<?xml version="1.0" encoding="utf-8"?>
<!-- This URDF was automatically created by SolidWorks to URDF Exporter! Originally created by Stephen Brawner (brawner@gmail.com) 
     Commit Version: 1.6.0-1-g15f4949  Build Version: 1.6.7594.29634
     For more information, please see http://wiki.ros.org/sw_urdf_exporter -->
<robot
  name="r3_2020">
  <link
    name="base_link">
    <inertial>
      <origin
        xyz="0.081493 7.5493E-05 0.11049"
        rpy="0 0 0" />
      <mass
        value="12.193" />
      <inertia
        ixx="0.13348"
        ixy="-4.7884E-05"
        ixz="-0.0051656"
        iyy="0.13115"
        iyz="4.4011E-07"
        izz="0.2352" />
    </inertial>
    <visual>
      <origin
        xyz="0 0 0"
        rpy="0 0 0" />
      <geometry>
        <mesh
          filename="package://r3_2020/meshes/base_link.STL" />
      </geometry>
      <material
        name="">
        <color
          rgba="0.75294 0.75294 0.75294 1" />
      </material>
    </visual>
    <collision>
      <origin
        xyz="0 0 0"
        rpy="0 0 0" />
      <geometry>
        <mesh
          filename="package://r3_2020/meshes/base_link.STL" />
      </geometry>
    </collision>
  </link>
  <link
    name="wheel_left_link">
    <inertial>
      <origin
        xyz="0.0014732 0.16692 0.051477"
        rpy="0 0 0" />
      <mass
        value="0.1194" />
      <inertia
        ixx="9.3714E-05"
        ixy="1.6276E-22"
        ixz="2.8309E-20"
        iyy="0.0001803"
        iyz="9.0387E-19"
        izz="9.3714E-05" />
    </inertial>
    <visual>
      <origin
        xyz="0 0 0"
        rpy="0 0 0" />
      <geometry>
        <mesh
          filename="package://r3_2020/meshes/wheel_left_link.STL" />
      </geometry>
      <material
        name="">
        <color
          rgba="1 1 1 1" />
      </material>
    </visual>
    <collision>
      <origin
        xyz="0 0 0"
        rpy="0 0 0" />
      <geometry>
        <mesh
          filename="package://r3_2020/meshes/wheel_left_link.STL" />
      </geometry>
    </collision>
  </link>
  <joint
    name="wheel_left_joint"
    type="continuous">
    <origin
      xyz="0 0 0"
      rpy="0 0 0" />
    <parent
      link="base_link" />
    <child
      link="wheel_left_link" />
    <axis
      xyz="0 -1 0" />
  </joint>
  <link
    name="wheel_right_link">
    <inertial>
      <origin
        xyz="-0.0014732 -0.16692 0.051477"
        rpy="0 0 0" />
      <mass
        value="0.1194" />
      <inertia
        ixx="9.3714E-05"
        ixy="-4.7723E-22"
        ixz="-2.4569E-20"
        iyy="0.0001803"
        iyz="3.0153E-19"
        izz="9.3714E-05" />
    </inertial>
    <visual>
      <origin
        xyz="0 0 0"
        rpy="0 0 0" />
      <geometry>
        <mesh
          filename="package://r3_2020/meshes/wheel_right_link.STL" />
      </geometry>
      <material
        name="">
        <color
          rgba="1 1 1 1" />
      </material>
    </visual>
    <collision>
      <origin
        xyz="0 0 0"
        rpy="0 0 0" />
      <geometry>
        <mesh
          filename="package://r3_2020/meshes/wheel_right_link.STL" />
      </geometry>
    </collision>
  </link>
  <joint
    name="wheel_right_joint"
    type="continuous">
    <origin
      xyz="0 0 0"
      rpy="0 0 0" />
    <parent
      link="base_link" />
    <child
      link="wheel_right_link" />
    <axis
      xyz="0 1 0" />
  </joint>
  <link
    name="blade_right_link">
    <inertial>
      <origin
        xyz="0.3015 -0.1503 0.13348"
        rpy="0 0 0" />
      <mass
        value="0.012885" />
      <inertia
        ixx="1.4009E-05"
        ixy="-1.5168E-20"
        ixz="-1.9721E-22"
        iyy="2.8016E-05"
        iyz="9.4703E-20"
        izz="1.4009E-05" />
    </inertial>
    <visual>
      <origin
        xyz="0 0 0"
        rpy="0 0 0" />
      <geometry>
        <mesh
          filename="package://r3_2020/meshes/blade_right_link.STL" />
      </geometry>
      <material
        name="">
        <color
          rgba="0.79216 0.81961 0.93333 1" />
      </material>
    </visual>
    <collision>
      <origin
        xyz="0 0 0"
        rpy="0 0 0" />
      <geometry>
        <mesh
          filename="package://r3_2020/meshes/blade_right_link.STL" />
      </geometry>
    </collision>
  </link>
  <joint
    name="blade_right_joint"
    type="continuous">
    <origin
      xyz="0 0 0"
      rpy="0 0 0" />
    <parent
      link="base_link" />
    <child
      link="blade_right_link" />
    <axis
      xyz="0 -1 0" />
  </joint>

  <transmission name="blade_right_trans">
        <type>transmission_interface/SimpleTransmission</type>
        <joint name="blade_right_joint">
            <hardwareInterface>VelocityJointInterface</hardwareInterface>
        </joint>
        <actuator name="blade_right_motor">
            <hardwareInterface>VelocityJointInterface</hardwareInterface>
            <mechanicalReduction>1</mechanicalReduction>
        </actuator>
    </transmission>
  <link
    name="blade_left_link">
    <inertial>
      <origin
        xyz="0.3015 0.1503 0.13348"
        rpy="0 0 0" />
      <mass
        value="0.012885" />
      <inertia
        ixx="1.4009E-05"
        ixy="1.3204E-20"
        ixz="5.0201E-22"
        iyy="2.8016E-05"
        iyz="8.3033E-26"
        izz="1.4009E-05" />
    </inertial>
    <visual>
      <origin
        xyz="0 0 0"
        rpy="0 0 0" />
      <geometry>
        <mesh
          filename="package://r3_2020/meshes/blade_left_link.STL" />
      </geometry>
      <material
        name="">
        <color
          rgba="0.79216 0.81961 0.93333 1" />
      </material>
    </visual>
    <collision>
      <origin
        xyz="0 0 0"
        rpy="0 0 0" />
      <geometry>
        <mesh
          filename="package://r3_2020/meshes/blade_left_link.STL" />
      </geometry>
    </collision>
  </link>
  <joint
    name="blade_left_joint"
    type="continuous">
    <origin
      xyz="0 0 0"
      rpy="0 0 0" />
    <parent
      link="base_link" />
    <child
      link="blade_left_link" />
    <axis
      xyz="0 -1 0" />
  </joint>

  <link
    name="sonar1_link">
    <inertial>
      <origin
        xyz="0 0 0"
        rpy="0 0 0" />
      <mass
        value="0.030" />
        <inertia
          ixx="0.0000005" ixy="0" ixz="0"
          iyy="0.0000005" iyz="0" izz="0.0000065" />
    </inertial>
    <visual>
      <origin
        xyz="0 0 0"
        rpy="0 0 0" />
      <geometry>
         <box size="0.01 0.05 0.01" />
      </geometry>
    </visual>
    <collision>
      <origin
        xyz="0 0 0"
        rpy="0 0 0" /> 
      <geometry>
        <box size="0.01 0.05 0.01" />       
      </geometry>
    </collision>
  </link>
  <joint
    name="sonar1_joint"
    type="fixed">
    <origin
      xyz="0.245 0 0.161"
      rpy="0 0 0" /> <!-- xyz= -0.235 0 0.16  rpy= 0 0 pi -->
    <parent
      link="base_link" />
    <child
      link="sonar1_link" />
    <axis
      xyz="0 -1 0" />
  </joint>
      <gazebo reference="sonar1_link">
      <sensor type="ray" name="sonar1_sensor">
        <pose> 0 0 0 0 0 0 </pose>
        <update_rate>60</update_rate> <!-- referensissä nimeämiskäytäntönä alaviiva-->
        <visualize>true</visualize>
        <ray>
          <scan>
            <horizontal>
              <samples>5</samples>
              <resolution>1.0</resolution>
              <min_angle>-0.05</min_angle>
              <max_angle>0.05</max_angle>
            </horizontal>
            <vertical>
              <samples>1</samples>
              <resolution>1.0</resolution>
              <min_angle>-0.05</min_angle>
              <max_angle>0.05</max_angle>
            </vertical>
          </scan>
          <range>   <!--luotauksen mittayksiköt metreinä-->
            <min>0.01</min>
            <max>5</max>      
            <resolution>0.01</resolution>
          </range>
        </ray>
        <plugin name="sonar1_controller" filename="libgazebo_ros_range.so">
          <gaussianNoise>0.005</gaussianNoise>
          <alwaysOn>true</alwaysOn>
          <updateRate>60</updateRate> <!-- pluginissa nimeämiskäytäntonä Isokirjain-->
          <topicName>sonar1</topicName>
          <frameName>sonar1_link</frameName>
          <minRange>0.01</minRange>
          <maxRange>0.5</maxRange>
          <fov>0.5</fov>
          <radiation>ultrasound</radiation>
        </plugin>
      </sensor>
    </gazebo>
  
  <link
    name="sonar2_link">
    <inertial>
      <origin
        xyz="0 0 0"
        rpy="0 0 0" />
      <mass
        value="0.030" />
        <inertia
          ixx="0.0000005" ixy="0" ixz="0"
          iyy="0.0000005" iyz="0" izz="0.0000065" />
    </inertial>
    <visual>
      <origin
        xyz="0 0 0"
        rpy="0 0 0" />
      <geometry>
         <box size="0.01 0.05 0.01" />
      </geometry>
    </visual>
    <collision>
      <origin
        xyz="0 0 0"
        rpy="0 0 0" /> 
      <geometry>
        <box size="0.01 0.05 0.01" />       
      </geometry>
    </collision>
  </link>
  <joint
    name="sonar2_joint"
    type="fixed">
    <origin
      xyz="-0.245 0 0.16"
      rpy="0 0 3.14159" />
    <parent
      link="base_link" />
    <child
      link="sonar2_link" />
    <axis
      xyz="0 -1 0" />
  </joint>
      <gazebo reference="sonar2_link">
      <sensor type="ray" name="sonar2_sensor">
        <pose> 0 0 0 0 0 0 </pose>
        <update_rate>60</update_rate> <!-- referensissä nimeämiskäytäntönä alaviiva-->
        <visualize>true</visualize>
        <ray>
          <scan>
            <horizontal>
              <samples>5</samples>
              <resolution>1.0</resolution>
              <min_angle>-0.05</min_angle>
              <max_angle>0.05</max_angle>
            </horizontal>
            <vertical>
              <samples>1</samples>
              <resolution>1.0</resolution>
              <min_angle>-0.05</min_angle>
              <max_angle>0.05</max_angle>
            </vertical>
          </scan>
          <range>   <!--luotauksen mittayksiköt metreinä-->
            <min>0.01</min>
            <max>5</max>      
            <resolution>0.01</resolution>
          </range>
        </ray>
        <plugin name="sonar2_controller" filename="libgazebo_ros_range.so">
          <gaussianNoise>0.005</gaussianNoise>
          <alwaysOn>true</alwaysOn>
          <updateRate>60</updateRate> <!-- pluginissa nimeämiskäytäntonä Isokirjain-->
          <topicName>sonar2</topicName>
          <frameName>sonar2_link</frameName>
          <minRange>0.01</minRange>
          <maxRange>0.5</maxRange>
          <fov>0.5</fov>
          <radiation>ultrasound</radiation>
        </plugin>
      </sensor>
    </gazebo>  

  <link
    name="sonar3_link">
    <inertial>
      <origin
        xyz="0 0 0"
        rpy="0 0 0" />
      <mass
        value="0.030" />
        <inertia
          ixx="0.0000005" ixy="0" ixz="0"
          iyy="0.0000005" iyz="0" izz="0.0000065" />
    </inertial>
    <visual>
      <origin
        xyz="0 0 0"
        rpy="0 0 0" />
      <geometry>
         <box size="0.01 0.05 0.01" />
      </geometry>
    </visual>
    <collision>
      <origin
        xyz="0 0 0"
        rpy="0 0 0" /> 
      <geometry>
        <box size="0.01 0.05 0.01" />       
      </geometry>
    </collision>
  </link>
  <joint
    name="sonar3_joint"
    type="fixed">
    <origin
      xyz="0.013 -0.245 0.165"
      rpy="0 0 4.71239" /> <!-- xyz="0.013 0.245 0.16"
      rpy="0 0 -1.57079" -->
    <parent
      link="base_link" />
    <child
      link="sonar3_link" />
    <axis
      xyz="0 -1 0" />
  </joint>
      <gazebo reference="sonar3_link">
      <sensor type="ray" name="sonar3_sensor">
        <pose> 0 0 0 0 0 0 </pose>
        <update_rate>60</update_rate> <!-- referensissä nimeämiskäytäntönä alaviiva-->
        <visualize>true</visualize>
        <ray>
          <scan>
            <horizontal>
              <samples>5</samples>
              <resolution>1.0</resolution>
              <min_angle>-0.05</min_angle>
              <max_angle>0.05</max_angle>
            </horizontal>
            <vertical>
              <samples>1</samples>
              <resolution>1.0</resolution>
              <min_angle>-0.05</min_angle>
              <max_angle>0.05</max_angle>
            </vertical>
          </scan>
          <range>   <!--luotauksen mittayksiköt metreinä-->
            <min>0.01</min>
            <max>5</max>      
            <resolution>0.01</resolution>
          </range>
        </ray>
        <plugin name="sonar3_controller" filename="libgazebo_ros_range.so">
          <gaussianNoise>0.005</gaussianNoise>
          <alwaysOn>true</alwaysOn>
          <updateRate>60</updateRate> <!-- pluginissa nimeämiskäytäntonä Isokirjain-->
          <topicName>sonar3</topicName>
          <frameName>sonar3_link</frameName>
          <minRange>0.01</minRange>
          <maxRange>0.5</maxRange>
          <fov>0.5</fov>
          <radiation>ultrasound</radiation>
        </plugin>
      </sensor>
    </gazebo>

  <link
    name="sonar4_link">
    <inertial>
      <origin
        xyz="0 0 0"
        rpy="0 0 0" />
      <mass
        value="0.030" />
        <inertia
          ixx="0.0000005" ixy="0" ixz="0"
          iyy="0.0000005" iyz="0" izz="0.0000065" />
    </inertial>
    <visual>
      <origin
        xyz="0 0 0"
        rpy="0 0 0" />
      <geometry>
         <box size="0.01 0.05 0.01" />
      </geometry>
    </visual>
    <collision>
      <origin
        xyz="0 0 0"
        rpy="0 0 0" /> 
      <geometry>
        <box size="0.01 0.05 0.01" />       
      </geometry>
    </collision>
  </link>
  <joint
    name="sonar4_joint"
    type="fixed">
    <origin
      xyz="0.013 0.245 0.16"
      rpy="0 0 1.57079" />
    <parent
      link="base_link" />
    <child
      link="sonar4_link" />
    <axis
      xyz="0 -1 0" />
  </joint>
      <gazebo reference="sonar4_link">
      <sensor type="ray" name="sonar4_sensor">
        <pose> 0 0 0 0 0 0 </pose>
        <update_rate>60</update_rate> <!-- referensissä nimeämiskäytäntönä alaviiva-->
        <visualize>true</visualize>
        <ray>
          <scan>
            <horizontal>
              <samples>5</samples>
              <resolution>1.0</resolution>
              <min_angle>-0.05</min_angle>
              <max_angle>0.05</max_angle>
            </horizontal>
            <vertical>
              <samples>1</samples>
              <resolution>1.0</resolution>
              <min_angle>-0.05</min_angle>
              <max_angle>0.05</max_angle>
            </vertical>
          </scan>
          <range>   <!--luotauksen mittayksiköt metreinä-->
            <min>0.01</min>
            <max>5</max>      
            <resolution>0.01</resolution>
          </range>
        </ray>
        <plugin name="sonar4_controller" filename="libgazebo_ros_range.so">
          <gaussianNoise>0.005</gaussianNoise>
          <alwaysOn>true</alwaysOn>
          <updateRate>60</updateRate> <!-- pluginissa nimeämiskäytäntonä Isokirjain-->
          <topicName>sonar4</topicName>
          <frameName>sonar4_link</frameName>
          <minRange>0.01</minRange>
          <maxRange>0.5</maxRange>
          <fov>0.5</fov>
          <radiation>ultrasound</radiation>
        </plugin>
      </sensor>
    </gazebo>

</robot>